Workbook

Sheet VENTAS
A1: Reference | B1: number | C1: Document | D1: sku | E1: Product | F1: Brand | G1: Type | H1: Family | I1: Line | J1: Sub Line | K1: clientNumber | L1: Customer | M1: Route Name | N1: routeVendor | O1: Sales Rep | P1: Truck Name | Q1: routeDriver | R1: deliveryDate | S1: Month | T1: Year | U1: Orig. Qty. | V1: Quantity | W1: Unit | X1: actualCost | Y1: Cost | Z1: Total Weight | AA1: Sale | AB1: Margin | AC1: Discount (Promotions) | AD1: Out of Code | AE1: Good Return | AF1: No Charge | AG1: quantity | AH1: Out of Code Units | AI1: Good Return Units | AJ1: noCharge
A2: 255-9010974 | B2: =VLOOKUP(A2,Sheet3!A:B,2,0) -> INV-205-2966 | C2: Invoice | D2: 92177 | E2: POCAS BUBLE T MATCHA 16.5/24CT | F2: POCAS | G2: BEBIDAS | H2: ------ | I2: ------ | J2: ------ | K2: 10406 | L2: Chevron #093679 | M2: 255 - Carlos Morales | N2: 205 | O2: Carlos Morales | P2: Sunmex Truck - 156 | Q2: 104 | R2: 02/16/2026 | S2: 02 | T2: 2026 | U2: 24 | V2: 24 | W2: UNIT(S) | X2: 1.89 | Y2: 1.14583 | Z2: 0 | AA2: 45.36 | AB2: 39.37% | AC2: 0 | AD2: 0 | AE2: 0 | AF2: 0 | AG2: 24 | AH2: 0 | AI2: 0 | AJ2: 0
A3: 255-9010974 | B3: =VLOOKUP(A3,Sheet3!A:B,2,0) -> INV-205-2966 | C3: Invoice | D3: 30937 | E3: SAB CHETO FLAMIN HOT 145G | F3: SABRITAS | G3: BOTANAS | H3: MAIZ | I3: CON QUESO | J3: CON CHILE | K3: 10406 | L3: Chevron #093679 | M3: 255 - Carlos Morales | N3: 205 | O3: Carlos Morales | P3: Sunmex Truck - 156 | Q3: 104 | R3: 02/16/2026 | S3: 02 | T3: 2026 | U3: 10 | V3: 10 | W3: UNIT(S) | X3: 2.79 | Y3: 1.99 | Z3: 0 | AA3: 27.9 | AB3: 28.67% | AC3: 0 | AD3: 0 | AE3: 0 | AF3: 0 | AG3: 10 | AH3: 0 | AI3: 0 | AJ3: 0
A4: 255-9010974 | B4: =VLOOKUP(A4,Sheet3!A:B,2,0) -> INV-205-2966 | C4: Invoice | D4: 19230 | E4: PARR ALOE WATERMELON 500M/20CT | F4: PARROT | G4: BEBIDAS | H4: JUGO DE FRUTAS | I4: ALOE VERA | J4: JUGO DE FRUTAS | K4: 10406 | L4: Chevron #093679 | M4: 255 - Carlos Morales | N4: 205 | O4: Carlos Morales | P4: Sunmex Truck - 156 | Q4: 104 | R4: 02/16/2026 | S4: 02 | T4: 2026 | U4: 20 | V4: 20 | W4: UNIT(S) | X4: 1.29 | Y4: 0.86 | Z4: 0 | AA4: 25.8 | AB4: 33.33% | AC4: 0 | AD4: 0 | AE4: 0 | AF4: 0 | AG4: 20 | AH4: 0 | AI4: 0 | AJ4: 0
A5: 255-9010974 | B5: =VLOOKUP(A5,Sheet3!A:B,2,0) -> INV-205-2966 | C5: Invoice | D5: 19207 | E5: PARR ALOE STRAWBERRY 500M/20CT | F5: PARROT | G5: BEBIDAS | H5: JUGO DE FRUTAS | I5: ALOE VERA | J5: JUGO DE FRUTAS | K5: 10406 | L5: Chevron #093679 | M5: 255 - Carlos Morales | N5: 205 | O5: Carlos Morales | P5: Sunmex Truck - 156 | Q5: 104 | R5: 02/16/2026 | S5: 02 | T5: 2026 | U5: 20 | V5: 20 | W5: UNIT(S) | X5: 1.29 | Y5: 0.86 | Z5: 0 | AA5: 25.8 | AB5: 33.33% | AC5: 0 | AD5: 0 | AE5: 0 | AF5: 0 | AG5: 20 | AH5: 0 | AI5: 0 | AJ5: 0
A6: 255-9010974 | B6: =VLOOKUP(A6,Sheet3!A:B,2,0) -> INV-205-2966 | C6: Invoice | D6: 66860 | E6: JUMEX CAN COCO-PINEAP 16OZ/12CT | F6: JUMEX | G6: BEBIDAS | H6: JUGO DE FRUTAS | I6: JUGO DE FRUTAS | J6: JUGO DE FRUTAS | K6: 10406 | L6: Chevron #093679 | M6: 255 - Carlos Morales | N6: 205 | O6: Carlos Morales | P6: Sunmex Truck - 156 | Q6: 104 | R6: 02/16/2026 | S6: 02 | T6: 2026 | U6: 12 | V6: 12 | W6: UNIT(S) | X6: 1.59 | Y6: 1.06 | Z6: 0 | AA6: 19.08 | AB6: 33.33% | AC6: 0 | AD6: 0 | AE6: 0 | AF6: 0 | AG6: 12 | AH6: 0 | AI6: 0 | AJ6: 0
A7: 255-9010974 | B7: =VLOOKUP(A7,Sheet3!A:B,2,0) -> INV-205-2966 | C7: Invoice | D7: 13976 | E7: DIANDI COYOTA CAJETA 9.52/14CT | F7: DIANDI | G7: PANES | H7: COYOTAS | I7: RELLENOS | J7: CAJETA | K7: 10406 | L7: Chevron #093679 | M7: 255 - Carlos Morales | N7: 205 | O7: Carlos Morales | P7: Sunmex Truck - 156 | Q7: 104 | R7: 02/16/2026 | S7: 02 | T7: 2026 | U7: 5 | V7: 5 | W7: UNIT(S) | X7: 2.53 | Y7: 1.68 | Z7: 0 | AA7: 12.65 | AB7: 33.6% | AC7: 0 | AD7: 0 | AE7: 0 | AF7: 0 | AG7: 5 | AH7: 0 | AI7: 0 | AJ7: 0
A8: 255-9010974 | B8: =VLOOKUP(A8,Sheet3!A:B,2,0) -> INV-205-2966 | C8: Invoice | D8: 13907 | E8: DIANDI COYOTA DUL LECH 9.52/14CT | F8: DIANDI | G8: PANES | H8: COYOTAS | I8: RELLENOS | J8: DULCE DE LECHE | K8: 10406 | L8: Chevron #093679 | M8: 255 - Carlos Morales | N8: 205 | O8: Carlos Morales | P8: Sunmex Truck - 156 | Q8: 104 | R8: 02/16/2026 | S8: 02 | T8: 2026 | U8: 5 | V8: 5 | W8: UNIT(S) | X8: 2.53 | Y8: 1.68 | Z8: 0 | AA8: 12.65 | AB8: 33.6% | AC8: 0 | AD8: 0 | AE8: 0 | AF8: 0 | AG8: 5 | AH8: 0 | AI8: 0 | AJ8: 0
A9: 255-9010974 | B9: =VLOOKUP(A9,Sheet3!A:B,2,0) -> INV-205-2966 | C9: Invoice | D9: 16580 | E9: GAMESA CREMAX FRESA 90G | F9: GAMESA | G9: GALLETAS | H9: GALLETAS DULCES | I9: ------ | J9: ------ | K9: 10406 | L9: Chevron #093679 | M9: 255 - Carlos Morales | N9: 205 | O9: Carlos Morales | P9: Sunmex Truck - 156 | Q9: 104 | R9: 02/16/2026 | S9: 02 | T9: 2026 | U9: 5 | V9: 5 | W9: UNIT(S) | X9: 2.09 | Y9: 1.35 | Z9: 0 | AA9: 10.45 | AB9: 35.41% | AC9: 0 | AD9: 0 | AE9: 0 | AF9: 0 | AG9: 5 | AH9: 0 | AI9: 0 | AJ9: 0
A10: 255-9010974 | B10: =VLOOKUP(A10,Sheet3!A:B,2,0) -> INV-205-2966 | C10: Invoice | D10: 16566 | E10: GAMESA CREMAX CHOCOLATE 90G | F10: GAMESA | G10: GALLETAS | H10: GALLETAS DULCES | I10: ------ | J10: ------ | K10: 10406 | L10: Chevron #093679 | M10: 255 - Carlos Morales | N10: 205 | O10: Carlos Morales | P10: Sunmex Truck - 156 | Q10: 104 | R10: 02/16/2026 | S10: 02 | T10: 2026 | U10: 5 | V10: 5 | W10: UNIT(S) | X10: 2.09 | Y10: 1.35 | Z10: 0 | AA10: 10.45 | AB10: 35.41% | AC10: 0 | AD10: 0 | AE10: 0 | AF10: 0 | AG10: 5 | AH10: 0 | AI10: 0 | AJ10: 0
A11: 255-9010974 | B11: =VLOOKUP(A11,Sheet3!A:B,2,0) -> INV-205-2966 | C11: Invoice | D11: 22502 | E11: GAMESA EMPERADOR PIRUETA 115G | F11: GAMESA | G11: GALLETAS | H11: GALLETAS DULCES | I11: ------ | J11: ------ | K11: 10406 | L11: Chevron #093679 | M11: 255 - Carlos Morales | N11: 205 | O11: Carlos Morales | P11: Sunmex Truck - 156 | Q11: 104 | R11: 02/16/2026 | S11: 02 | T11: 2026 | U11: 5 | V11: 5 | W11: UNIT(S) | X11: 2.09 | Y11: 1.4 | Z11: 0 | AA11: 10.45 | AB11: 33.01% | AC11: 0 | AD11: 0 | AE11: 0 | AF11: 0 | AG11: 5 | AH11: 0 | AI11: 0 | AJ11: 0
A12: 255-9010974 | B12: =VLOOKUP(A12,Sheet3!A:B,2,0) -> INV-205-2966 | C12: Invoice | D12: 35726 | E12: GAMESA ARCOIRIS 75G | F12: GAMESA | G12: GALLETAS | H12: GALLETAS DULCES | I12: ------ | J12: ------ | K12: 10406 | L12: Chevron #093679 | M12: 255 - Carlos Morales | N12: 205 | O12: Carlos Morales | P12: Sunmex Truck - 156 | Q12: 104 | R12: 02/16/2026 | S12: 02 | T12: 2026 | U12: 5 | V12: 5 | W12: UNIT(S) | X12: 2.09 | Y12: 1.4 | Z12: 0 | AA12: 10.45 | AB12: 33.01% | AC12: 0 | AD12: 0 | AE12: 0 | AF12: 0 | AG12: 5 | AH12: 0 | AI12: 0 | AJ12: 0
A13: 255-9010974 | B13: =VLOOKUP(A13,Sheet3!A:B,2,0) -> INV-205-2966 | C13: Invoice | D13: 23608 | E13: GAMESA MARAVILLAS 112G | F13: GAMESA | G13: GALLETAS | H13: GALLETAS DULCES | I13: ------ | J13: ------ | K13: 10406 | L13: Chevron #093679 | M13: 255 - Carlos Morales | N13: 205 | O13: Carlos Morales | P13: Sunmex Truck - 156 | Q13: 104 | R13: 02/16/2026 | S13: 02 | T13: 2026 | U13: 5 | V13: 5 | W13: UNIT(S) | X13: 2.09 | Y13: 1.4 | Z13: 0 | AA13: 10.45 | AB13: 33.01% | AC13: 0 | AD13: 0 | AE13: 0 | AF13: 0 | AG13: 5 | AH13: 0 | AI13: 0 | AJ13: 0
... A1202: 256-9009423 | B1202: =VLOOKUP(A1202,Sheet3!A:B,2,0) -> INV-206-3015 | C1202: Invoice | D1202: 14745 | E1202: COCA COLA 3 LITER / 6CT | F1202: COCA COLA FAMILIAR | G1202: BEBIDAS | H1202: BEBIDA CON SABOR | I1202: BEBIDA CON GAS | J1202: BEBIDA CON GAS | K1202: 10578 | L1202: El Alamo Supercarniceria at Chandler | M1202: 256 - Ana Ibarra | N1202: 206 | O1202: Ana Ibarra | P1202: Sunmex Truck - 151 | Q1202: 101 | R1202: 02/16/2026 | S1202: 02 | T1202: 2026 | U1202: 6 | V1202: 6 | W1202: UNIT(S) | X1202: 4.49 | Y1202: 3.183333 | Z1202: 0 | AA1202: 26.94 | AB1202: 29.1% | AC1202: 0 | AD1202: 0 | AE1202: 0 | AF1202: 0 | AG1202: 6 | AH1202: 0 | AI1202: 0 | AJ1202: 0
A1203: 379-000679 | B1203: =VLOOKUP(A1203,Sheet3!A:B,2,0) -> INV-001-3075 | C1203: Invoice | D1203: 31118 | E1203: SAB FRITO CHILE LIMON 170G | F1203: SABRITAS | G1203: BOTANAS | H1203: MAIZ | I1203: CON CHILE | J1203: CON LIMON | K1203: 10976 | L1203: Phx Samples | M1203: 379 - Venta Piso | N1203: 001 | O1203: NoCharge Samples | Q1203: 001 | R1203: 02/16/2026 | S1203: 02 | T1203: 2026 | U1203: 18 | V1203: 18 | W1203: UNIT(S) | X1203: 1.99 | Y1203: 1.99 | Z1203: 0 | AA1203: 0 | AB1203: 0 | AC1203: 35.82 | AD1203: 0 | AE1203: 0 | AF1203: 35.82 | AG1203: 0 | AH1203: 0 | AI1203: 0 | AJ1203: 18
A1204: 379-000679 | B1204: =VLOOKUP(A1204,Sheet3!A:B,2,0) -> INV-001-3075 | C1204: Invoice | D1204: 30920 | E1204: SAB CHETO BOLITAS 110G | F1204: SABRITAS | G1204: BOTANAS | H1204: MAIZ | I1204: CON QUESO | J1204: CON CHILE | K1204: 10976 | L1204: Phx Samples | M1204: 379 - Venta Piso | N1204: 001 | O1204: NoCharge Samples | Q1204: 001 | R1204: 02/16/2026 | S1204: 02 | T1204: 2026 | U1204: 40 | V1204: 40 | W1204: UNIT(S) | X1204: 1.99 | Y1204: 1.99 | Z1204: 0 | AA1204: 0 | AB1204: 0 | AC1204: 79.6 | AD1204: 0 | AE1204: 0 | AF1204: 79.6 | AG1204: 0 | AH1204: 0 | AI1204: 0 | AJ1204: 40
A1205: 379-000679 | B1205: =VLOOKUP(A1205,Sheet3!A:B,2,0) -> INV-001-3075 | C1205: Invoice | D1205: 21269 | E1205: BARCEL RUNNER 200GR | F1205: BARCEL | G1205: BOTANAS | H1205: MAIZ | I1205: ------ | J1205: ------ | K1205: 10976 | L1205: Phx Samples | M1205: 379 - Venta Piso | N1205: 001 | O1205: NoCharge Samples | Q1205: 001 | R1205: 02/16/2026 | S1205: 02 | T1205: 2026 | U1205: 6 | V1205: 6 | W1205: UNIT(S) | X1205: 2.55 | Y1205: 2.55 | Z1205: 0 | AA1205: 0 | AB1205: 0 | AC1205: 15.3 | AD1205: 0 | AE1205: 0 | AF1205: 15.3 | AG1205: 0 | AH1205: 0 | AI1205: 0 | AJ1205: 6
A1206: 379-000679 | B1206: =VLOOKUP(A1206,Sheet3!A:B,2,0) -> INV-001-3075 | C1206: Invoice | D1206: 44405 | E1206: SAB PAKETAXO DARK 208GR | F1206: SABRITAS | G1206: BOTANAS | H1206: ------ | I1206: ------ | J1206: ------ | K1206: 10976 | L1206: Phx Samples | M1206: 379 - Venta Piso | N1206: 001 | O1206: NoCharge Samples | Q1206: 001 | R1206: 02/16/2026 | S1206: 02 | T1206: 2026 | U1206: 7 | V1206: 7 | W1206: UNIT(S) | X1206: 3.05 | Y1206: 3.05 | Z1206: 0 | AA1206: 0 | AB1206: 0 | AC1206: 21.35 | AD1206: 0 | AE1206: 0 | AF1206: 21.35 | AG1206: 0 | AH1206: 0 | AI1206: 0 | AJ1206: 7
A1207: 259-9000560 | B1207: =VLOOKUP(A1207,Sheet3!A:B,2,0) -> INV-001-3055 | C1207: Invoice | D1207: 31064 | E1207: SAB DORITO NACHOS 146G | F1207: SABRITAS | G1207: BOTANAS | H1207: MAIZ | I1207: CON QUESO | J1207: CON CHILE | K1207: 11719 | L1207: NC Distributor LLC. | M1207: 259 - Venta Administrativa | N1207: 001 | O1207: Ventas Administrativas | P1207: Sunmex Truck - 152 | Q1207: 001 | R1207: 02/17/2026 | S1207: 02 | T1207: 2026 | U1207: 552 | V1207: 552 | W1207: UNIT(S) | X1207: 2.1 | Y1207: 1.99 | Z1207: 0 | AA1207: 1159.2 | AB1207: 38.1% | AC1207: 380.88 | AD1207: 0 | AE1207: 0 | AF1207: 0 | AG1207: 552 | AH1207: 0 | AI1207: 0 | AJ1207: 0
A1208: 259-9000560 | B1208: =VLOOKUP(A1208,Sheet3!A:B,2,0) -> INV-001-3055 | C1208: Invoice | D1208: 30937 | E1208: SAB CHETO FLAMIN HOT 145G | F1208: SABRITAS | G1208: BOTANAS | H1208: MAIZ | I1208: CON QUESO | J1208: CON CHILE | K1208: 11719 | L1208: NC Distributor LLC. | M1208: 259 - Venta Administrativa | N1208: 001 | O1208: Ventas Administrativas | P1208: Sunmex Truck - 152 | Q1208: 001 | R1208: 02/17/2026 | S1208: 02 | T1208: 2026 | U1208: 300 | V1208: 300 | W1208: UNIT(S) | X1208: 2.1 | Y1208: 1.99 | Z1208: 0 | AA1208: 630 | AB1208: 38.1% | AC1208: 207 | AD1208: 0 | AE1208: 0 | AF1208: 0 | AG1208: 300 | AH1208: 0 | AI1208: 0 | AJ1208: 0
A1209: 259-9000560 | B1209: =VLOOKUP(A1209,Sheet3!A:B,2,0) -> INV-001-3055 | C1209: Invoice | D1209: 30869 | E1209: SAB TOSTITO SALSA 175G | F1209: SABRITAS | G1209: BOTANAS | H1209: MAIZ | I1209: CON SALSA VERDE | J1209: CON SABOR | K1209: 11719 | L1209: NC Distributor LLC. | M1209: 259 - Venta Administrativa | N1209: 001 | O1209: Ventas Administrativas | P1209: Sunmex Truck - 152 | Q1209: 001 | R1209: 02/17/2026 | S1209: 02 | T1209: 2026 | U1209: 286 | V1209: 286 | W1209: UNIT(S) | X1209: 2.1 | Y1209: 1.99 | Z1209: 0 | AA1209: 600.6 | AB1209: 38.1% | AC1209: 197.34 | AD1209: 0 | AE1209: 0 | AF1209: 0 | AG1209: 286 | AH1209: 0 | AI1209: 0 | AJ1209: 0
A1210: 259-9000560 | B1210: =VLOOKUP(A1210,Sheet3!A:B,2,0) -> INV-001-3055 | C1210: Invoice | D1210: 51062 | E1210: SAB FRITO CHORIZO 170G | F1210: SABRITAS | G1210: BOTANAS | H1210: MAIZ | I1210: CON CHORIZO | J1210: CON CHIPOTLE | K1210: 11719 | L1210: NC Distributor LLC. | M1210: 259 - Venta Administrativa | N1210: 001 | O1210: Ventas Administrativas | P1210: Sunmex Truck - 152 | Q1210: 001 | R1210: 02/17/2026 | S1210: 02 | T1210: 2026 | U1210: 44 | V1210: 44 | W1210: UNIT(S) | X1210: 2.1 | Y1210: 1.99 | Z1210: 0 | AA1210: 92.4 | AB1210: 38.1% | AC1210: 30.36 | AD1210: 0 | AE1210: 0 | AF1210: 0 | AG1210: 44 | AH1210: 0 | AI1210: 0 | AJ1210: 0
A1211: 259-9000560 | B1211: =VLOOKUP(A1211,Sheet3!A:B,2,0) -> INV-001-3055 | C1211: Invoice | D1211: 31125 | E1211: SAB FRITO LIMON SAL 170G | F1211: SABRITAS | G1211: BOTANAS | H1211: MAIZ | I1211: CON SAL | J1211: CON LIMON | K1211: 11719 | L1211: NC Distributor LLC. | M1211: 259 - Venta Administrativa | N1211: 001 | O1211: Ventas Administrativas | P1211: Sunmex Truck - 152 | Q1211: 001 | R1211: 02/17/2026 | S1211: 02 | T1211: 2026 | U1211: 44 | V1211: 44 | W1211: UNIT(S) | X1211: 2.1 | Y1211: 1.99 | Z1211: 0 | AA1211: 92.4 | AB1211: 38.1% | AC1211: 30.36 | AD1211: 0 | AE1211: 0 | AF1211: 0 | AG1211: 44 | AH1211: 0 | AI1211: 0 | AJ1211: 0
A1212: 256-9009433 | B1212: =VLOOKUP(A1212,Sheet3!A:B,2,0) -> INV-206-3023 | C1212: Invoice | D1212: 16548 | E1212: NESCAFE DOLCA 170G/15CT | F1212: NESCAFE | G1212: ABARROTES | H1212: CAFE | I1212: INSTANTANEAS | J1212: ------ | K1212: 11716 | L1212: Carniceria Sonora #4 | M1212: 256 - Ana Ibarra | N1212: 206 | O1212: Ana Ibarra | P1212: Sunmex Truck - 156 | Q1212: 104 | R1212: 02/17/2026 | S1212: 02 | T1212: 2026 | U1212: 15 | V1212: 15 | W1212: UNIT(S) | X1212: 7.55 | Y1212: 5.86666 | Z1212: 0 | AA1212: 113.25 | AB1212: 33.42% | AC1212: 12.6 | AD1212: 0 | AE1212: 0 | AF1212: 0 | AG1212: 15 | AH1212: 0 | AI1212: 0 | AJ1212: 0
A1213: 256-9009433 | B1213: =VLOOKUP(A1213,Sheet3!A:B,2,0) -> INV-206-3023 | C1213: Invoice | D1213: 14745 | E1213: COCA COLA 3 LITER / 6CT | F1213: COCA COLA FAMILIAR | G1213: BEBIDAS | H1213: BEBIDA CON SABOR | I1213: BEBIDA CON GAS | J1213: BEBIDA CON GAS | K1213: 11716 | L1213: Carniceria Sonora #4 | M1213: 256 - Ana Ibarra | N1213: 206 | O1213: Ana Ibarra | P1213: Sunmex Truck - 156 | Q1213: 104 | R1213: 02/17/2026 | S1213: 02 | T1213: 2026 | U1213: 24 | V1213: 24 | W1213: UNIT(S) | X1213: 3.99 | Y1213: 3.183333 | Z1213: 0 | AA1213: 95.76 | AB1213: 32.75% | AC1213: 12 | AD1213: 0 | AE1213: 0 | AF1213: 0 | AG1213: 24 | AH1213: 0 | AI1213: 0 | AJ1213: 0
A1214: 256-9009433 | B1214: =VLOOKUP(A1214,Sheet3!A:B,2,0) -> INV-206-3023 | C1214: Invoice | D1214: 38206 | E1214: KIDSM YO YO MANIA 12CT | F1214: KIDSMANIA | G1214: JUGUETES | H1214: ------ | I1214: ------ | J1214: ------ | K1214: 11716 | L1214: Carniceria Sonora #4 | M1214: 256 - Ana Ibarra | N1214: 206 | O1214: Ana Ibarra | P1214: Sunmex Truck - 156 | Q1214: 104 | R1214: 02/17/2026 | S1214: 02 | T1214: 2026 | U1214: 4 | V1214: 4 | W1214: UNIT(S) | X1214: 16.01 | Y1214: 11 | Z1214: 0 | AA1214: 64.04 | AB1214: 37.41% | AC1214: 3.92 | AD1214: 0 | AE1214: 0 | AF1214: 0 | AG1214: 4 | AH1214: 0 | AI1214: 0 | AJ1214: 0
A1215: 256-9009433 | B1215: =VLOOKUP(A1215,Sheet3!A:B,2,0) -> INV-206-3023 | C1215: Invoice | D1215: 10577 | E1215: 1-2-3 VEGETAL OIL 1LT/15CT | F1215: 1-2-3 | G1215: ABARROTES | H1215: ACEITE | I1215: VEGETAL | J1215: COMESTIBLE | K1215: 11716 | L1215: Carniceria Sonora #4 | M1215: 256 - Ana Ibarra | N1215: 206 | O1215: Ana Ibarra | P1215: Sunmex Truck - 156 | Q1215: 104 | R1215: 02/17/2026 | S1215: 02 | T1215: 2026 | U1215: 15 | V1215: 15 | W1215: UNIT(S) | X1215: 3.59 | Y1215: 2.89 | Z1215: 0 | AA1215: 53.85 | AB1215: 30.64% | AC1215: 6 | AD1215: 0 | AE1215: 0 | AF1215: 0 | AG1215: 15 | AH1215: 0 | AI1215: 0 | AJ1215: 0
A1216: 256-9009433 | B1216: =VLOOKUP(A1216,Sheet3!A:B,2,0) -> INV-206-3023 | C1216: Invoice | D1216: 10374 | E1216: TOPO CHICO MINERAL 355ML/24CT | F1216: TOPO CHICO | G1216: BEBIDAS | H1216: BEBIDA GASEOSA | I1216: ------ | J1216: ------ | K1216: 11716 | L1216: Carniceria Sonora #4 | M1216: 256 - Ana Ibarra | N1216: 206 | O1216: Ana Ibarra | P1216: Sunmex Truck - 156 | Q1216: 104 | R1216: 02/17/2026 | S1216: 02 | T1216: 2026 | U1216: 24 | V1216: 24 | W1216: UNIT(S) | X1216: 1.64 | Y1216: 1.28 | Z1216: 0 | AA1216: 39.36 | AB1216: 32.93% | AC1216: 4.32 | AD1216: 0 | AE1216: 0 | AF1216: 0 | AG1216: 24 | AH1216: 0 | AI1216: 0 | AJ1216: 0
A1217: 256-9009433 | B1217: =VLOOKUP(A1217,Sheet3!A:B,2,0) -> INV-206-3023 | C1217: Invoice | D1217: 19216 | E1217: PARR ALOE MANGO 1.5 LT/12CT | F1217: PARROT | G1217: BEBIDAS | H1217: JUGO DE FRUTAS | I1217: ALOE VERA | J1217: JUGO DE FRUTAS | K1217: 11716 | L1217: Carniceria Sonora #4 | M1217: 256 - Ana Ibarra | N1217: 206 | O1217: Ana Ibarra | P1217: Sunmex Truck - 156 | Q1217: 104 | R1217: 02/17/2026 | S1217: 02 | T1217: 2026 | U1217: 12 | V1217: 12 | W1217: UNIT(S) | X1217: 2.7 | Y1217: 2.079166 | Z1217: 0 | AA1217: 32.4 | AB1217: 33.73% | AC1217: 3.48 | AD1217: 0 | AE1217: 0 | AF1217: 0 | AG1217: 12 | AH1217: 0 | AI1217: 0 | AJ1217: 0
A1218: 256-9009433 | B1218: =VLOOKUP(A1218,Sheet3!A:B,2,0) -> INV-206-3023 | C1218: Invoice | D1218: 19217 | E1218: PARR ALOE POMEGRANATE 1.5LT/12CT | F1218: PARROT | G1218: BEBIDAS | H1218: JUGO DE FRUTAS | I1218: ALOE VERA | J1218: JUGO DE FRUTAS | K1218: 11716 | L1218: Carniceria Sonora #4 | M1218: 256 - Ana Ibarra | N1218: 206 | O1218: Ana Ibarra | P1218: Sunmex Truck - 156 | Q1218: 104 | R1218: 02/17/2026 | S1218: 02 | T1218: 2026 | U1218: 12 | V1218: 12 | W1218: UNIT(S) | X1218: 2.7 | Y1218: 2.07916 | Z1218: 0 | AA1218: 32.4 | AB1218: 33.73% | AC1218: 3.48 | AD1218: 0 | AE1218: 0 | AF1218: 0 | AG1218: 12 | AH1218: 0 | AI1218: 0 | AJ1218: 0
A1219: 256-9009433 | B1219: =VLOOKUP(A1219,Sheet3!A:B,2,0) -> INV-206-3023 | C1219: Invoice | D1219: 13457 | E1219: DIANDI MINI BESITO NUEZ 160/12CT | F1219: DIANDI GALLETAS | G1219: GALLETAS | H1219: ------ | I1219: ------ | J1219: ------ | K1219: 11716 | L1219: Carniceria Sonora #4 | M1219: 256 - Ana Ibarra | N1219: 206 | O1219: Ana Ibarra | P1219: Sunmex Truck - 156 | Q1219: 104 | R1219: 02/17/2026 | S1219: 02 | T1219: 2026 | U1219: 12 | V1219: 12 | W1219: UNIT(S) | X1219: 2.49 | Y1219: 2.1 | Z1219: 0 | AA1219: 29.88 | AB1219: 15.66% | AC1219: 0 | AD1219: 0 | AE1219: 0 | AF1219: 0 | AG1219: 12 | AH1219: 0 | AI1219: 0 | AJ1219: 0
A1220: 256-9009433 | B1220: =VLOOKUP(A1220,Sheet3!A:B,2,0) -> INV-206-3023 | C1220: Invoice | D1220: 15918 | E1220: VIVE 100 ORIGINAL 600ML/24CT | F1220: VIVE 100 | G1220: BEBIDAS | H1220: ENERGETICOS | I1220: BEBIDA CON SABOR | J1220: BEBIDA CON SABOR | K1220: 11716 | L1220: Carniceria Sonora #4 | M1220: 256 - Ana Ibarra | N1220: 206 | O1220: Ana Ibarra | P1220: Sunmex Truck - 156 | Q1220: 104 | R1220: 02/17/2026 | S1220: 02 | T1220: 2026 | U1220: 24 | V1220: 24 | W1220: UNIT(S) | X1220: 1.2 | Y1220: 0.81 | Z1220: 0 | AA1220: 28.8 | AB1220: 43.33% | AC1220: 3.12 | AD1220: 0 | AE1220: 0 | AF1220: 0 | AG1220: 24 | AH1220: 0 | AI1220: 0 | AJ1220: 0
A1221: 256-9009433 | B1221: =VLOOKUP(A1221,Sheet3!A:B,2,0) -> INV-206-3023 | C1221: Invoice | D1221: 30003 | E1221: LUC GUMIES WATERMELN 12UN 4.58 | F1221: LUCAS | G1221: DULCES | H1221: ------ | I1221: ------ | J1221: ------ | K1221: 11716 | L1221: Carniceria Sonora #4 | M1221: 256 - Ana Ibarra | N1221: 206 | O1221: Ana Ibarra | P1221: Sunmex Truck - 156 | Q1221: 104 | R1221: 02/17/2026 | S1221: 02 | T1221: 2026 | U1221: 1 | V1221: 1 | W1221: UNIT(S) | X1221: 26.09 | Y1221: 19 | Z1221: 0 | AA1221: 26.09 | AB1221: 38.29% | AC1221: 2.9 | AD1221: 0 | AE1221: 0 | AF1221: 0 | AG1221: 1 | AH1221: 0 | AI1221: 0 | AJ1221: 0
A1222: 256-9009433 | B1222: =VLOOKUP(A1222,Sheet3!A:B,2,0) -> INV-206-3023 | C1222: Invoice | D1222: 30016 | E1222: HUICHOL TRADITIONAL 6.5OZ/24CT | F1222: SALSA HUICHOL | G1222: ABARROTES | H1222: SALSAS | I1222: CON CHILE | J1222: CON CHILE | K1222: 11716 | L1222: Carniceria Sonora #4 | M1222: 256 - Ana Ibarra | N1222: 206 | O1222: Ana Ibarra | P1222: Sunmex Truck - 156 | Q1222: 104 | R1222: 02/17/2026 | S1222: 02 | T1222: 2026 | U1222: 24 | V1222: 24 | W1222: UNIT(S) | X1222: 1.07 | Y1222: 0.79 | Z1222: 0 | AA1222: 25.68 | AB1222: 37.38% | AC1222: 2.88 | AD1222: 0 | AE1222: 0 | AF1222: 0 | AG1222: 24 | AH1222: 0 | AI1222: 0 | AJ1222: 0
A1223: 256-9009433 | B1223: =VLOOKUP(A1223,Sheet3!A:B,2,0) -> INV-206-3023 | C1223: Invoice | D1223: 14813 | E1223: FRESCA TORONJA 3 LITER / 6CT | F1223: COCA COLA FAMILIAR | G1223: BEBIDAS | H1223: BEBIDA CON SABOR | I1223: BEBIDA CON GAS | J1223: BEBIDA CON GAS | K1223: 11716 | L1223: Carniceria Sonora #4 | M1223: 256 - Ana Ibarra | N1223: 206 | O1223: Ana Ibarra | P1223: Sunmex Truck - 156 | Q1223: 104 | R1223: 02/17/2026 | S1223: 02 | T1223: 2026 | U1223: 6 | V1223: 6 | W1223: UNIT(S) | X1223: 3.99 | Y1223: 3.183333 | Z1223: 0 | AA1223: 23.94 | AB1223: 32.75% | AC1223: 3 | AD1223: 0 | AE1223: 0 | AF1223: 0 | AG1223: 6 | AH1223: 0 | AI1223: 0 | AJ1223: 0
... A1358: 255-9010982 | B1358: =VLOOKUP(A1358,Sheet3!A:B,2,0) -> INV-205-2974 | C1358: Invoice | D1358: 21086 | E1358: GAMESA BARRAS DE COCO 106G | F1358: GAMESA | G1358: GALLETAS | H1358: GALLETAS DULCES | I1358: ------ | J1358: ------ | K1358: 10444 | L1358: Chevron #355144 | M1358: 255 - Carlos Morales | N1358: 205 | O1358: Carlos Morales | P1358: Sunmex Truck - 159 | Q1358: 105 | R1358: 02/17/2026 | S1358: 02 | T1358: 2026 | U1358: 5 | V1358: 5 | W1358: UNIT(S) | X1358: 2.09 | Y1358: 1.35 | Z1358: 0 | AA1358: 10.45 | AB1358: 35.41% | AC1358: 0 | AD1358: 0 | AE1358: 0 | AF1358: 0 | AG1358: 5 | AH1358: 0 | AI1358: 0 | AJ1358: 0
A1359: 259-9000560 | B1359: =VLOOKUP(A1359,Sheet3!A:B,2,0) -> INV-001-3055 | C1359: Invoice | D1359: 67674 | E1359: SAB RUFFLE QUESO 120G | F1359: SABRITAS | G1359: BOTANAS | H1359: MAIZ | I1359: CON QUESO | J1359: CON SABOR | K1359: 11719 | L1359: NC Distributor LLC. | M1359: 259 - Venta Administrativa | N1359: 001 | O1359: Ventas Administrativas | P1359: Sunmex Truck - 152 | Q1359: 001 | R1359: 02/17/2026 | S1359: 02 | T1359: 2026 | U1359: 840 | V1359: 840 | W1359: UNIT(S) | X1359: 2.1 | Y1359: 1.99 | Z1359: 0 | AA1359: 1764 | AB1359: 38.1% | AC1359: 579.6 | AD1359: 0 | AE1359: 0 | AF1359: 0 | AG1359: 840 | AH1359: 0 | AI1359: 0 | AJ1359: 0
A1360: 255-9010982 | B1360: =VLOOKUP(A1360,Sheet3!A:B,2,0) -> INV-205-2974 | C1360: Invoice | D1360: 16216 | E1360: PARR COKIE STRAWBERRY SAND/24CT | F1360: PARROT | G1360: GALLETAS | H1360: GALLETAS DULCES | I1360: CON SABOR | J1360: GALLETAS | K1360: 10444 | L1360: Chevron #355144 | M1360: 255 - Carlos Morales | N1360: 205 | O1360: Carlos Morales | P1360: Sunmex Truck - 159 | Q1360: 105 | R1360: 02/17/2026 | S1360: 02 | T1360: 2026 | U1360: 6 | V1360: 6 | W1360: UNIT(S) | X1360: 1.73 | Y1360: 1.07083 | Z1360: 0 | AA1360: 10.38 | AB1360: 38.1% | AC1360: 0 | AD1360: 0 | AE1360: 0 | AF1360: 0 | AG1360: 6 | AH1360: 0 | AI1360: 0 | AJ1360: 0
A1361: 255-9010982 | B1361: =VLOOKUP(A1361,Sheet3!A:B,2,0) -> INV-205-2974 | C1361: Invoice | D1361: 16220 | E1361: PARR COKIE PINK GUAVA SAND/24CT | F1361: PARROT | G1361: GALLETAS | H1361: GALLETAS DULCES | I1361: CON SABOR | J1361: GALLETAS | K1361: 10444 | L1361: Chevron #355144 | M1361: 255 - Carlos Morales | N1361: 205 | O1361: Carlos Morales | P1361: Sunmex Truck - 159 | Q1361: 105 | R1361: 02/17/2026 | S1361: 02 | T1361: 2026 | U1361: 3 | V1361: 5 | W1361: UNIT(S) | X1361: 1.73 | Y1361: 1.0208 | Z1361: 0 | AA1361: 8.65 | AB1361: 40.99% | AC1361: 0 | AD1361: 0 | AE1361: 0 | AF1361: 0 | AG1361: 5 | AH1361: 0 | AI1361: 0 | AJ1361: 0
A1362: 255-9010988 | B1362: =VLOOKUP(A1362,Sheet3!A:B,2,0) -> INV-205-2979 | C1362: Invoice | D1362: 24037 | E1362: PARR CAN MANGO 485ML/12CT | F1362: PARROT | G1362: BEBIDAS | H1362: JUGO DE FRUTAS | I1362: AGUA DE COCO | J1362: JUGO DE FRUTAS | K1362: 11144 | L1362: Quick Stop / Mcdowell | M1362: 255 - Carlos Morales | N1362: 205 | O1362: Carlos Morales | P1362: Sunmex Truck - 159 | Q1362: 105 | R1362: 02/17/2026 | S1362: 02 | T1362: 2026 | U1362: 12 | V1362: 12 | W1362: UNIT(S) | X1362: 1.583 | Y1362: 0.94583 | Z1362: 0 | AA1362: 18.996 | AB1362: 40.25% | AC1362: 0 | AD1362: 0 | AE1362: 0 | AF1362: 0 | AG1362: 12 | AH1362: 0 | AI1362: 0 | AJ1362: 0
...

Sheet CREDITOS
A1: Reference | B1: number | C1: Document | D1: sku | E1: Product | F1: Brand | G1: Type | H1: Family | I1: Line | J1: Sub Line | K1: clientNumber | L1: Customer | M1: Route Name | N1: routeVendor | O1: Sales Rep | P1: Truck Name | Q1: routeDriver | R1: returnedAt | S1: Month | T1: Year | U1: Orig. Qty. | V1: Quantity | W1: Unit | X1: actualCost | Y1: Cost | Z1: Total Weight | AA1: Sale | AB1: Margin | AC1: Discount (Promotions) | AD1: out of code | AE1: Good Return | AF1: No Charge | AG1: Sale Units | AH1: creditMemo | AI1: goodReturn | AJ1: noCost
A2: 255-9010974 | B2: CRM-205-1952 | C2: Invoice | D2: 51086 | E2: SAB SABRITONES 160G | F2: SABRITAS | G2: BOTANAS | H2: CHICHARRONES | I2: CON CHILE | J2: CON LIMON | K2: 10406 | L2: Chevron #093679 | M2: 255 - Carlos Morales | N2: 205 | O2: Carlos Morales | P2: Sunmex Truck - 156 | Q2: 104 | R2: 02/16/2026 | S2: 02 | T2: 2026 | U2: 1 | V2: 1 | W2: UNIT(S) | X2: 3.29 | Y2: 1.99 | Z2: 0 | AA2: 0 | AB2: 0 | AC2: 0 | AD2: 3.29 | AE2: 0 | AF2: 0 | AG2: 0 | AH2: 1 | AI2: 0 | AJ2: 0
A3: 255-9010974 | B3: CRM-205-1952 | C3: Invoice | D3: 24038 | E3: PARR CAN POMEGRANATE 485/12CT | F3: PARROT | G3: BEBIDAS | H3: JUGO DE FRUTAS | I3: AGUA DE COCO | J3: JUGO DE FRUTAS | K3: 10406 | L3: Chevron #093679 | M3: 255 - Carlos Morales | N3: 205 | O3: Carlos Morales | P3: Sunmex Truck - 156 | Q3: 104 | R3: 02/16/2026 | S3: 02 | T3: 2026 | U3: 12 | V3: 12 | W3: UNIT(S) | X3: 1.583 | Y3: 0.94583 | Z3: 0 | AA3: 0 | AB3: 0 | AC3: 0 | AD3: 0 | AE3: 18.996 | AF3: 0 | AG3: 0 | AH3: 0 | AI3: 12 | AJ3: 0
A4: 255-9010975 | B4: CRM-205-1953 | C4: Invoice | D4: 14517 | E4: SAB RANCHERITOS 145G | F4: SABRITAS | G4: BOTANAS | H4: MAIZ | I4: CON CHILE | J4: CON SABOR | K4: 11226 | L4: PVM Sinclair | M4: 255 - Carlos Morales | N4: 205 | O4: Carlos Morales | P4: Sunmex Truck - 156 | Q4: 104 | R4: 02/16/2026 | S4: 02 | T4: 2026 | U4: 1 | V4: 1 | W4: UNIT(S) | X4: 2.49 | Y4: 1.99 | Z4: 0 | AA4: 0 | AB4: 0 | AC4: 0 | AD4: 2.49 | AE4: 0 | AF4: 0 | AG4: 0 | AH4: 1 | AI4: 0 | AJ4: 0
A5: 255-9010975 | B5: CRM-205-1953 | C5: Invoice | D5: 25541 | E5: SAB FAM DORITO MIX 205G | F5: SABRITAS | G5: BOTANAS | H5: ------ | I5: ------ | J5: ------ | K5: 11226 | L5: PVM Sinclair | M5: 255 - Carlos Morales | N5: 205 | O5: Carlos Morales | P5: Sunmex Truck - 156 | Q5: 104 | R5: 02/16/2026 | S5: 02 | T5: 2026 | U5: 4 | V5: 4 | W5: UNIT(S) | X5: 4.29 | Y5: 3.05 | Z5: 0 | AA5: 0 | AB5: 0 | AC5: 0 | AD5: 17.16 | AE5: 0 | AF5: 0 | AG5: 0 | AH5: 4 | AI5: 0 | AJ5: 0
A6: 255-9010977 | B6: CRM-205-1954 | C6: Invoice | D6: 55008 | E6: SAB PAKETAXO AZUL 208G | F6: SABRITAS | G6: BOTANAS | H6: PAPAS | I6: ------ | J6: ------ | K6: 11329 | L6: Stop & Shop | M6: 255 - Carlos Morales | N6: 205 | O6: Carlos Morales | P6: Sunmex Truck - 156 | Q6: 104 | R6: 02/16/2026 | S6: 02 | T6: 2026 | U6: 2 | V6: 2 | W6: UNIT(S) | X6: 4.29 | Y6: 3.05 | Z6: 0 | AA6: 0 | AB6: 0 | AC6: 0 | AD6: 8.58 | AE6: 0 | AF6: 0 | AG6: 0 | AH6: 2 | AI6: 0 | AJ6: 0
A7: 255-9010977 | B7: CRM-205-1954 | C7: Invoice | D7: 51062 | E7: SAB FRITO CHORIZO 170G | F7: SABRITAS | G7: BOTANAS | H7: MAIZ | I7: CON CHORIZO | J7: CON CHIPOTLE | K7: 11329 | L7: Stop & Shop | M7: 255 - Carlos Morales | N7: 205 | O7: Carlos Morales | P7: Sunmex Truck - 156 | Q7: 104 | R7: 02/16/2026 | S7: 02 | T7: 2026 | U7: 4 | V7: 4 | W7: UNIT(S) | X7: 2.79 | Y7: 1.99 | Z7: 0 | AA7: 0 | AB7: 0 | AC7: 0 | AD7: 11.16 | AE7: 0 | AF7: 0 | AG7: 0 | AH7: 4 | AI7: 0 | AJ7: 0
A8: 255-9010977 | B8: CRM-205-1954 | C8: Invoice | D8: 66234 | E8: BARCEL CHIP JALAPENO 170G | F8: BARCEL | G8: BOTANAS | H8: PAPAS | I8: CON SABOR | J8: ------ | K8: 11329 | L8: Stop & Shop | M8: 255 - Carlos Morales | N8: 205 | O8: Carlos Morales | P8: Sunmex Truck - 156 | Q8: 104 | R8: 02/16/2026 | S8: 02 | T8: 2026 | U8: 3 | V8: 3 | W8: UNIT(S) | X8: 5.19 | Y8: 3.45 | Z8: 0 | AA8: 0 | AB8: 0 | AC8: 0 | AD8: 15.57 | AE8: 0 | AF8: 0 | AG8: 0 | AH8: 3 | AI8: 0 | AJ8: 0
A9: 254-9011977 | B9: CRM-204-1931 | C9: Invoice | D9: 41729 | E9: DIANDI CANDLE SPARK BLUE SPANISH | F9: VIG PARTY | G9: ABARROTES | H9: VELAS | I9: ------ | J9: ------ | K9: 10104 | L9: Speedway Liquor | M9: 254 - Yurithzin Perez | N9: 204 | O9: Yurithzin Perez | P9: Sunmex Truck - 156 | Q9: 104 | R9: 02/16/2026 | S9: 02 | T9: 2026 | U9: 7 | V9: 7 | W9: UNIT(S) | X9: 2.99 | Y9: 1.86 | Z9: 0 | AA9: 0 | AB9: 0 | AC9: 0 | AD9: 20.93 | AE9: 0 | AF9: 0 | AG9: 0 | AH9: 7 | AI9: 0 | AJ9: 0
A10: 251-9012469 | B10: CRM-201-1865 | C10: Invoice | D10: 13907 | E10: DIANDI COYOTA DUL LECH 9.52/14CT | F10: DIANDI | G10: PANES | H10: COYOTAS | I10: RELLENOS | J10: DULCE DE LECHE | K10: 10672 | L10: Food City #140 | M10: 251 - Manuel Ayala | N10: 201 | O10: Manuel Ayala | P10: Sunmex Truck - 153 | Q10: 103 | R10: 02/16/2026 | S10: 02 | T10: 2026 | U10: 7 | V10: 7 | W10: UNIT(S) | X10: 2.35 | Y10: 1.68 | Z10: 0 | AA10: 0 | AB10: 0 | AC10: 0 | AD10: 16.45 | AE10: 0 | AF10: 0 | AG10: 0 | AH10: 7 | AI10: 0 | AJ10: 0
A11: 251-9012471 | B11: CRM-201-1866 | C11: Invoice | D11: 31118 | E11: SAB FRITO CHILE LIMON 170G | F11: SABRITAS | G11: BOTANAS | H11: MAIZ | I11: CON CHILE | J11: CON LIMON | K11: 10672 | L11: Food City #140 | M11: 251 - Manuel Ayala | N11: 201 | O11: Manuel Ayala | P11: Sunmex Truck - 153 | Q11: 103 | R11: 02/16/2026 | S11: 02 | T11: 2026 | U11: 7 | V11: 7 | W11: UNIT(S) | X11: 2.99 | Y11: 1.99 | Z11: 0 | AA11: 0 | AB11: 0 | AC11: 0 | AD11: 20.93 | AE11: 0 | AF11: 0 | AG11: 0 | AH11: 7 | AI11: 0 | AJ11: 0
A12: 251-9012471 | B12: CRM-201-1866 | C12: Invoice | D12: 31125 | E12: SAB FRITO LIMON SAL 170G | F12: SABRITAS | G12: BOTANAS | H12: MAIZ | I12: CON SAL | J12: CON LIMON | K12: 10672 | L12: Food City #140 | M12: 251 - Manuel Ayala | N12: 201 | O12: Manuel Ayala | P12: Sunmex Truck - 153 | Q12: 103 | R12: 02/16/2026 | S12: 02 | T12: 2026 | U12: 12 | V12: 12 | W12: UNIT(S) | X12: 2.99 | Y12: 1.99 | Z12: 0 | AA12: 0 | AB12: 0 | AC12: 0 | AD12: 35.88 | AE12: 0 | AF12: 0 | AG12: 0 | AH12: 12 | AI12: 0 | AJ12: 0
A13: 255-9010972 | B13: CRM-205-1951 | C13: Invoice | D13: 30682 | E13: SAB FAM RUFFLE MIX 170G | F13: SABRITAS | G13: BOTANAS | H13: ------ | I13: ------ | J13: ------ | K13: 11899 | L13: Sinclair/Washington | M13: 255 - Carlos Morales | N13: 205 | O13: Carlos Morales | P13: Sunmex Truck - 151 | Q13: 101 | R13: 02/16/2026 | S13: 02 | T13: 2026 | U13: 1 | V13: 1 | W13: UNIT(S) | X13: 4.29 | Y13: 3.05 | Z13: 0 | AA13: 0 | AB13: 0 | AC13: 0 | AD13: 4.29 | AE13: 0 | AF13: 0 | AG13: 0 | AH13: 1 | AI13: 0 | AJ13: 0
... A582: 252-010830 | B582: CRM-202-1882 | C582: Credit Memo | D582: 13860 | E582: DIANDI COYOTA JAMONCIL 9.52/14CT | F582: DIANDI | G582: PANES | H582: COYOTAS | I582: RELLENOS | J582: JAMONCILLO | K582: 10659 | L582: Food City #105 | M582: 252 - Daisy Burciaga | N582: 202 | O582: Daisy Burciaga | P582: Sunmex Truck - 153 | Q582: 103 | R582: 02/20/2026 | S582: 02 | T582: 2026 | U582: 1 | V582: 1 | W582: UNIT(S) | X582: 2.35 | Y582: 1.68 | Z582: 0 | AA582: 0 | AB582: 0 | AC582: 0 | AD582: 2.35 | AE582: 0 | AF582: 0 | AG582: 0 | AH582: 1 | AI582: 0 | AJ582: 0

Sheet Sheet3
A3: Row Labels
A4: 251-9012470 | B4: INV-201-2757
A5: 251-9012474 | B5: INV-201-2758
A6: 251-9012475 | B6: INV-201-2759
A7: 251-9012476 | B7: INV-201-2760
A8: 251-9012477 | B8: INV-201-2761
A9: 251-9012479 | B9: INV-201-2762
A10: 251-9012480 | B10: INV-201-2763
A11: 251-9012481 | B11: INV-201-2764
A12: 251-9012482 | B12: INV-201-2765
A13: 251-9012483 | B13: INV-201-2766
A14: 251-9012484 | B14: INV-201-2767
A15: 251-9012485 | B15: INV-201-2768
... A331: 381-000762 | B331: INV-252-3084
A332: (blank)
A333: Grand Total

Sheet Sheet2
A3: Row Labels
A4: 251-9012469 | B4: CRM-201-1865
A5: 251-9012471 | B5: CRM-201-1866
A6: 251-9012472 | B6: CRM-201-1867
A7: 251-9012473 | B7: CRM-201-1868
A8: 251-9012477 | B8: CRM-201-1869
A9: 251-9012478 | B9: CRM-201-1870
A10: 251-9012481 | B10: CRM-201-1871
A11: 251-9012483 | B11: CRM-201-1872
A12: 251-9012488 | B12: CRM-201-1873
A13: 251-9012492 | B13: CRM-201-1874
A14: 251-9012504 | B14: CRM-201-1875
A15: 251-9012505 | B15: CRM-201-1876
... A150: 381-000757 | B150: CRM-252-2011
A151: (blank)
A152: Grand Total
